<?xml version="1.0"?>
<robot name="diff_drive_robot_with_arm">

  <!-- Base -->
  <link name="base_link">
    <visual>
      <origin xyz="0 0 0.05" rpy="0 0 0"/>
      <geometry>
        <box size="0.4 0.3 0.1"/>
      </geometry>
      <material name="gray"><color rgba="0.6 0.6 0.6 1"/></material>
    </visual>
  </link>

  <!-- Wheels -->
  <link name="left_wheel">
    <visual>
      <origin xyz="0 0 0" rpy="1.5708 0 0"/>
      <geometry>
        <cylinder radius="0.05" length="0.02"/>
      </geometry>
      <material name="blue"><color rgba="0 0.5 1 1"/></material>
    </visual>
  </link>

  <joint name="left_wheel_joint" type="continuous">
    <parent link="base_link"/>
    <child link="left_wheel"/>
    <origin xyz="0 0.15 0.05"/>
    <axis xyz="0 0 1"/>
  </joint>

  <link name="right_wheel">
    <visual>
      <origin xyz="0 0 0" rpy="1.5708 0 0"/>
      <geometry>
        <cylinder radius="0.05" length="0.02"/>
      </geometry>
      <material name="blue"><color rgba="0 0.5 1 1"/></material>
    </visual>
  </link>

  <joint name="right_wheel_joint" type="continuous">
    <parent link="base_link"/>
    <child link="right_wheel"/>
    <origin xyz="0 -0.15 0.05"/>
    <axis xyz="0 0 1"/>
  </joint>

  <!-- Arm Link 1 -->
  <link name="arm_link_1">
    <visual>
      <origin xyz="0 0 0.15" rpy="0 0 0"/>
      <geometry>
        <box size="0.05 0.05 0.3"/>
      </geometry>
      <material name="red"><color rgba="1 0 0 1"/></material>
    </visual>
  </link>

  <joint name="shoulder_joint" type="revolute">
    <parent link="base_link"/>
    <child link="arm_link_1"/>
    <origin xyz="0 0 0.1"/>
    <axis xyz="0 1 0"/>
    <limit lower="-1.57" upper="1.57" effort="10" velocity="1"/>
  </joint>

  <!-- Arm Link 2 -->
  <link name="arm_link_2">
    <visual>
      <origin xyz="0 0 0.15" rpy="0 0 0"/>
      <geometry>
        <box size="0.05 0.05 0.3"/>
      </geometry>
      <material name="green"><color rgba="0 1 0 1"/></material>
    </visual>
  </link>

  <joint name="elbow_joint" type="revolute">
    <parent link="arm_link_1"/>
    <child link="arm_link_2"/>
    <origin xyz="0 0 0.3"/>
    <axis xyz="0 1 0"/>
    <limit lower="-1.57" upper="1.57" effort="10" velocity="1"/>
  </joint>

</robot>
