<?xml version="1.0"?>
<robot name="four_wheel_robot">

  <!-- Base Link -->
  <link name="base_link">
    <visual>
      <origin xyz="0 0 0.1" rpy="0 0 0"/>
      <geometry>
        <box size="0.6 0.4 0.2"/>
      </geometry>
      <material name="gray">
        <color rgba="0.6 0.6 0.6 1"/>
      </material>
    </visual>
  </link>

  <!-- Wheel Links (Cylinder aligned along Z axis) -->
  <link name="front_left_wheel">
    <visual>
      <origin xyz="0 0 0" rpy="0 0 0"/>
      <geometry>
        <cylinder radius="0.05" length="0.02"/>
      </geometry>
      <material name="dark_blue">
        <color rgba="0.0 0.0 0.8 1"/>
      </material>
    </visual>
  </link>

  <link name="front_right_wheel">
    <visual>
      <origin xyz="0 0 0" rpy="0 0 0"/>
      <geometry>
        <cylinder radius="0.05" length="0.02"/>
      </geometry>
      <material name="dark_blue">
        <color rgba="0.0 0.0 0.8 1"/>
      </material>
    </visual>
  </link>

  <link name="rear_left_wheel">
    <visual>
      <origin xyz="0 0 0" rpy="0 0 0"/>
      <geometry>
        <cylinder radius="0.05" length="0.02"/>
      </geometry>
      <material name="dark_blue">
        <color rgba="0.0 0.0 0.8 1"/>
      </material>
    </visual>
  </link>

  <link name="rear_right_wheel">
    <visual>
      <origin xyz="0 0 0" rpy="0 0 0"/>
      <geometry>
        <cylinder radius="0.05" length="0.02"/>
      </geometry>
      <material name="dark_blue">
        <color rgba="0.0 0.0 0.8 1"/>
      </material>
    </visual>
  </link>

  <!-- Wheel Joints (rotate geometry using joint origin) -->
  <joint name="front_left_wheel_joint" type="continuous">
    <parent link="base_link"/>
    <child link="front_left_wheel"/>
    <origin xyz="0.25 0.2 0.05" rpy="0 1.5708 0"/>
    <axis xyz="0 0 1"/>
  </joint>

  <joint name="front_right_wheel_joint" type="continuous">
    <parent link="base_link"/>
    <child link="front_right_wheel"/>
    <origin xyz="0.25 -0.2 0.05" rpy="0 1.5708 0"/>
    <axis xyz="0 0 1"/>
  </joint>

  <joint name="rear_left_wheel_joint" type="continuous">
    <parent link="base_link"/>
    <child link="rear_left_wheel"/>
    <origin xyz="-0.25 0.2 0.05" rpy="0 1.5708 0"/>
    <axis xyz="0 0 1"/>
  </joint>

  <joint name="rear_right_wheel_joint" type="continuous">
    <parent link="base_link"/>
    <child link="rear_right_wheel"/>
    <origin xyz="-0.25 -0.2 0.05" rpy="0 1.5708 0"/>
    <axis xyz="0 0 1"/>
  </joint>

</robot>
